============================= test session starts =============================
platform win32 -- Python 3.8.5, pytest-6.1.2, py-1.9.0, pluggy-0.13.1
rootdir: D:\devops\labs\my_devops_course\lab_2
collected 5 items

tests\tests.py ...F.                                                     [100%]

================================== FAILURES ===================================
__________________________ TestClass.test_my_method ___________________________

self = <tests.tests.TestClass testMethod=test_my_method>

    def test_my_method(self):
>       self.assertTrue(self.test_result == "Добрий день!")
E       AssertionError: False is not true

tests\tests.py:13: AssertionError
=========================== short test summary info ===========================
FAILED tests/tests.py::TestClass::test_my_method - AssertionError: False is n...
========================= 1 failed, 4 passed in 0.77s =========================
========================================
Результат без параметрів: 
No URL passed to function
========================================
Результат з правильною URL: 
Time is:  11:58:21 AM
Date is:  11-06-2020
Good day!
